Workbook

Sheet Порівняння
A1: ZON Wivenhoe — порівняння сценаріїв
A2: Усі показники рахуються з аркушів сценаріїв. Ціни, вартість будівництва і земля — ПРИПУЩЕННЯ (див. «Припущення»), а не підтверджені дані.
A4: Показник | B4: A: 25 бунгало (RM) | C4: B: бриф 25 + Hub | D4: Різниця B − A
A5: Житлових юнітів | B5: ='Сценарій A'!$B$15 -> 25 | C5: ='Сценарій B'!$B$15 -> 29 | D5: =C5-B5 -> 4
A6: Баланс території, м² | B6: ='Сценарій A'!$B$25 -> -908.3 | C6: ='Сценарій B'!$B$25 -> -1778.3 | D6: =C6-B6 -> -870
A7: Перевірка території | B7: ='Сценарій A'!$B$26 -> НЕ ВМІЩУЄТЬСЯ | C7: ='Сценарій B'!$B$26 -> НЕ ВМІЩУЄТЬСЯ
A8: Середня ділянка, м² | B8: ='Сценарій A'!$B$27 -> 412.4 | C8: ='Сценарій B'!$B$27 -> 411.2 | D8: =C8-B8 -> -1.2
A9: Доступних юнітів | B9: ='Сценарій A'!$B$31 -> 8 | C9: ='Сценарій B'!$B$31 -> 9 | D9: =C9-B9 -> 1
A10: GDV | B10: ='Сценарій A'!$B$37 -> 9163150 | C10: ='Сценарій B'!$B$37 -> 10231060 | D10: =C10-B10 -> 1067910
A11: TDC | B11: ='Сценарій A'!$B$53 -> 10150492 | C11: ='Сценарій B'!$B$53 -> 11876065 | D11: =C11-B11 -> 1725572.6
A12: Прибуток | B12: ='Сценарій A'!$B$56 -> -987342.19 | C12: ='Сценарій B'!$B$56 -> -1645004.8 | D12: =C12-B12 -> -657662.63
A13: Маржа на GDV | B13: ='Сценарій A'!$B$57 -> -0.10775139 | C13: ='Сценарій B'!$B$57 -> -0.16078537 | D13: =C13-B13 -> -0.05303398
A14: Проти цілі | B14: ='Сценарій A'!$B$59 -> НИЖЧЕ ЦІЛІ | C14: ='Сценарій B'!$B$59 -> НИЖЧЕ ЦІЛІ
A15: Макс. ціна землі (RLV) | B15: ='Сценарій A'!$B$60 -> -754534.85 | C15: ='Сценарій B'!$B$60 -> -1241952.8 | D15: =C15-B15 -> -487417.92
A16: Потрібна зміна цін для цілі | B16: ='Сценарій A'!$B$66 -> 0.39709857 | C16: ='Сценарій B'!$B$66 -> 0.46552952 | D16: =C16-B16 -> 0.068430943
A17: Ймовірність дозволу | B17: ='Сценарій A'!$B$12 -> 0.85 | C17: ='Сценарій B'!$B$12 -> 0.45 | D17: =C17-B17 -> -0.4
A18: Прибуток з поправкою на ризик | B18: ='Сценарій A'!$B$61 -> -854240.86 | C18: ='Сценарій B'!$B$61 -> -877752.17 | D18: =C18-B18 -> -23511.307
A21: Чутливість прибутку — Сценарій A (фінансування — константа)
A22: Ціна продажу ↓ / Вартість будівництва → | B22: -0.1 | C22: -0.05 | D22: 0 | E22: 0.05 | F22: 0.1
A23: -0.1 | B23: ='Сценарій A'!$B$37*(1+$A23)*(1-Припущення!$B$33)-'Сценарій A'!$B$64*(1+B$22)-'Сценарій A'!$B$65 -> -1191197.8 | C23: ='Сценарій A'!$B$37*(1+$A23)*(1-Припущення!$B$33)-'Сценарій A'!$B$64*(1+C$22)-'Сценарій A'!$B$65 -> -1535973.6 | D23: ='Сценарій A'!$B$37*(1+$A23)*(1-Припущення!$B$33)-'Сценарій A'!$B$64*(1+D$22)-'Сценарій A'!$B$65 -> -1880749.3 | E23: ='Сценарій A'!$B$37*(1+$A23)*(1-Припущення!$B$33)-'Сценарій A'!$B$64*(1+E$22)-'Сценарій A'!$B$65 -> -2225525.1 | F23: ='Сценарій A'!$B$37*(1+$A23)*(1-Припущення!$B$33)-'Сценарій A'!$B$64*(1+F$22)-'Сценарій A'!$B$65 -> -2570300.8
A24: -0.05 | B24: ='Сценарій A'!$B$37*(1+$A24)*(1-Припущення!$B$33)-'Сценарій A'!$B$64*(1+B$22)-'Сценарій A'!$B$65 -> -744494.25 | C24: ='Сценарій A'!$B$37*(1+$A24)*(1-Припущення!$B$33)-'Сценарій A'!$B$64*(1+C$22)-'Сценарій A'!$B$65 -> -1089270 | D24: ='Сценарій A'!$B$37*(1+$A24)*(1-Припущення!$B$33)-'Сценарій A'!$B$64*(1+D$22)-'Сценарій A'!$B$65 -> -1434045.8 | E24: ='Сценарій A'!$B$37*(1+$A24)*(1-Припущення!$B$33)-'Сценарій A'!$B$64*(1+E$22)-'Сценарій A'!$B$65 -> -1778821.5 | F24: ='Сценарій A'!$B$37*(1+$A24)*(1-Припущення!$B$33)-'Сценарій A'!$B$64*(1+F$22)-'Сценарій A'!$B$65 -> -2123597.2
A25: 0 | B25: ='Сценарій A'!$B$37*(1+$A25)*(1-Припущення!$B$33)-'Сценарій A'!$B$64*(1+B$22)-'Сценарій A'!$B$65 -> -297790.69 | C25: ='Сценарій A'!$B$37*(1+$A25)*(1-Припущення!$B$33)-'Сценарій A'!$B$64*(1+C$22)-'Сценарій A'!$B$65 -> -642566.44 | D25: ='Сценарій A'!$B$37*(1+$A25)*(1-Припущення!$B$33)-'Сценарій A'!$B$64*(1+D$22)-'Сценарій A'!$B$65 -> -987342.19 | E25: ='Сценарій A'!$B$37*(1+$A25)*(1-Припущення!$B$33)-'Сценарій A'!$B$64*(1+E$22)-'Сценарій A'!$B$65 -> -1332117.9 | F25: ='Сценарій A'!$B$37*(1+$A25)*(1-Припущення!$B$33)-'Сценарій A'!$B$64*(1+F$22)-'Сценарій A'!$B$65 -> -1676893.7
A26: 0.05 | B26: ='Сценарій A'!$B$37*(1+$A26)*(1-Припущення!$B$33)-'Сценарій A'!$B$64*(1+B$22)-'Сценарій A'!$B$65 -> 148912.88 | C26: ='Сценарій A'!$B$37*(1+$A26)*(1-Припущення!$B$33)-'Сценарій A'!$B$64*(1+C$22)-'Сценарій A'!$B$65 -> -195862.88 | D26: ='Сценарій A'!$B$37*(1+$A26)*(1-Припущення!$B$33)-'Сценарій A'!$B$64*(1+D$22)-'Сценарій A'!$B$65 -> -540638.62 | E26: ='Сценарій A'!$B$37*(1+$A26)*(1-Припущення!$B$33)-'Сценарій A'!$B$64*(1+E$22)-'Сценарій A'!$B$65 -> -885414.38 | F26: ='Сценарій A'!$B$37*(1+$A26)*(1-Припущення!$B$33)-'Сценарій A'!$B$64*(1+F$22)-'Сценарій A'!$B$65 -> -1230190.1
A27: 0.1 | B27: ='Сценарій A'!$B$37*(1+$A27)*(1-Припущення!$B$33)-'Сценарій A'!$B$64*(1+B$22)-'Сценарій A'!$B$65 -> 595616.44 | C27: ='Сценарій A'!$B$37*(1+$A27)*(1-Припущення!$B$33)-'Сценарій A'!$B$64*(1+C$22)-'Сценарій A'!$B$65 -> 250840.69 | D27: ='Сценарій A'!$B$37*(1+$A27)*(1-Припущення!$B$33)-'Сценарій A'!$B$64*(1+D$22)-'Сценарій A'!$B$65 -> -93935.062 | E27: ='Сценарій A'!$B$37*(1+$A27)*(1-Припущення!$B$33)-'Сценарій A'!$B$64*(1+E$22)-'Сценарій A'!$B$65 -> -438710.81 | F27: ='Сценарій A'!$B$37*(1+$A27)*(1-Припущення!$B$33)-'Сценарій A'!$B$64*(1+F$22)-'Сценарій A'!$B$65 -> -783486.56
A30: Чутливість прибутку — Сценарій B (фінансування — константа)
A31: Ціна продажу ↓ / Вартість будівництва → | B31: -0.1 | C31: -0.05 | D31: 0 | E31: 0.05 | F31: 0.1
A32: -0.1 | B32: ='Сценарій B'!$B$37*(1+$A32)*(1-Припущення!$B$33)-'Сценарій B'!$B$64*(1+B$31)-'Сценарій B'!$B$65 -> -1817134.5 | C32: ='Сценарій B'!$B$37*(1+$A32)*(1-Припущення!$B$33)-'Сценарій B'!$B$64*(1+C$31)-'Сценарій B'!$B$65 -> -2229833.8 | D32: ='Сценарій B'!$B$37*(1+$A32)*(1-Припущення!$B$33)-'Сценарій B'!$B$64*(1+D$31)-'Сценарій B'!$B$65 -> -2642533.2 | E32: ='Сценарій B'!$B$37*(1+$A32)*(1-Припущення!$B$33)-'Сценарій B'!$B$64*(1+E$31)-'Сценарій B'!$B$65 -> -3055232.5 | F32: ='Сценарій B'!$B$37*(1+$A32)*(1-Припущення!$B$33)-'Сценарій B'!$B$64*(1+F$31)-'Сценарій B'!$B$65 -> -3467931.9
A33: -0.05 | B33: ='Сценарій B'!$B$37*(1+$A33)*(1-Припущення!$B$33)-'Сценарій B'!$B$64*(1+B$31)-'Сценарій B'!$B$65 -> -1318370.3 | C33: ='Сценарій B'!$B$37*(1+$A33)*(1-Припущення!$B$33)-'Сценарій B'!$B$64*(1+C$31)-'Сценарій B'!$B$65 -> -1731069.6 | D33: ='Сценарій B'!$B$37*(1+$A33)*(1-Припущення!$B$33)-'Сценарій B'!$B$64*(1+D$31)-'Сценарій B'!$B$65 -> -2143769 | E33: ='Сценарій B'!$B$37*(1+$A33)*(1-Припущення!$B$33)-'Сценарій B'!$B$64*(1+E$31)-'Сценарій B'!$B$65 -> -2556468.3 | F33: ='Сценарій B'!$B$37*(1+$A33)*(1-Припущення!$B$33)-'Сценарій B'!$B$64*(1+F$31)-'Сценарій B'!$B$65 -> -2969167.7
A34: 0 | B34: ='Сценарій B'!$B$37*(1+$A34)*(1-Припущення!$B$33)-'Сценарій B'!$B$64*(1+B$31)-'Сценарій B'!$B$65 -> -819606.11 | C34: ='Сценарій B'!$B$37*(1+$A34)*(1-Припущення!$B$33)-'Сценарій B'!$B$64*(1+C$31)-'Сценарій B'!$B$65 -> -1232305.5 | D34: ='Сценарій B'!$B$37*(1+$A34)*(1-Припущення!$B$33)-'Сценарій B'!$B$64*(1+D$31)-'Сценарій B'!$B$65 -> -1645004.8 | E34: ='Сценарій B'!$B$37*(1+$A34)*(1-Припущення!$B$33)-'Сценарій B'!$B$64*(1+E$31)-'Сценарій B'!$B$65 -> -2057704.2 | F34: ='Сценарій B'!$B$37*(1+$A34)*(1-Припущення!$B$33)-'Сценарій B'!$B$64*(1+F$31)-'Сценарій B'!$B$65 -> -2470403.5
A35: 0.05 | B35: ='Сценарій B'!$B$37*(1+$A35)*(1-Припущення!$B$33)-'Сценарій B'!$B$64*(1+B$31)-'Сценарій B'!$B$65 -> -320841.94 | C35: ='Сценарій B'!$B$37*(1+$A35)*(1-Припущення!$B$33)-'Сценарій B'!$B$64*(1+C$31)-'Сценарій B'!$B$65 -> -733541.29 | D35: ='Сценарій B'!$B$37*(1+$A35)*(1-Припущення!$B$33)-'Сценарій B'!$B$64*(1+D$31)-'Сценарій B'!$B$65 -> -1146240.6 | E35: ='Сценарій B'!$B$37*(1+$A35)*(1-Припущення!$B$33)-'Сценарій B'!$B$64*(1+E$31)-'Сценарій B'!$B$65 -> -1558940 | F35: ='Сценарій B'!$B$37*(1+$A35)*(1-Припущення!$B$33)-'Сценарій B'!$B$64*(1+F$31)-'Сценарій B'!$B$65 -> -1971639.3
A36: 0.1 | B36: ='Сценарій B'!$B$37*(1+$A36)*(1-Припущення!$B$33)-'Сценарій B'!$B$64*(1+B$31)-'Сценарій B'!$B$65 -> 177922.23 | C36: ='Сценарій B'!$B$37*(1+$A36)*(1-Припущення!$B$33)-'Сценарій B'!$B$64*(1+C$31)-'Сценарій B'!$B$65 -> -234777.11 | D36: ='Сценарій B'!$B$37*(1+$A36)*(1-Припущення!$B$33)-'Сценарій B'!$B$64*(1+D$31)-'Сценарій B'!$B$65 -> -647476.46 | E36: ='Сценарій B'!$B$37*(1+$A36)*(1-Припущення!$B$33)-'Сценарій B'!$B$64*(1+E$31)-'Сценарій B'!$B$65 -> -1060175.8 | F36: ='Сценарій B'!$B$37*(1+$A36)*(1-Припущення!$B$33)-'Сценарій B'!$B$64*(1+F$31)-'Сценарій B'!$B$65 -> -1472875.2

Sheet Покращений випадок
A1: Improved Case — важелі поверх сценарію A (25 бунгало)
A2: Кожен важіль рахується окремо від бази сценарію A. Сині клітинки — припущення важелів (з запропонованої стратегії), жовті — ті, що найбільше впливають і потребують підтвердження.
A4: База: сценарій A
A5: GDV бази | B5: ='Сценарій A'!$B$37 -> 9163150
A6: Прибуток бази | B6: ='Сценарій A'!$B$56 -> -987342.19
A7: Маржа бази | B7: ='Сценарій A'!$B$57 -> -0.10775139
A9: 1. ZON Hub — продаж за капіталізованою вартістю (без апартаментів)
A10: Чистий річний дохід Hub | B10: 27500 | C10: стратегія: £25–30k; потрібен договір з оператором
A11: Ставка капіталізації | B11: 0.07 | C11: стратегія: 7%; для кав'ярні реалістичніше 8–10%
A12: Повна вартість Hub (будівля + fit-out) | B12: 390000 | C12: стратегія: £390k ≈ £2 230/м² на 175 м² — перевірити QS
A13: Капіталізована вартість | B13: =$B$10/$B$11 -> 392857.14
A14: Приріст прибутку від Hub | B14: =$B$13*(1-Припущення!$B$33)-$B$12 -> -6964.2857 | C14: у сценарії A Hub не закладено, тож віднімаємо і його вартість
A16: 2. Пакети ZON Ready
A17: Ринкових юнітів (без доступного житла) | B17: ='Сценарій A'!$B$15-'Сценарій A'!$B$31 -> 17 | C17: RSL не купує апгрейди
A18: Частка покупців, що беруть пакет | B18: 0.6 | C18: стратегія припускала 100% на 25 юнітів
A19: Ціна пакета | B19: 35000 | C19: стратегія
A20: Собівартість пакета | B20: 20000 | C20: стратегія
A21: Пакетів продано | B21: =ROUND($B$17*$B$18,0) -> 10
A22: Додаткова виручка | B22: =$B$21*$B$19 -> 350000
A23: Приріст прибутку від пакетів | B23: =$B$21*($B$19*(1-Припущення!$B$33)-$B$20) -> 141250
A25: 3. Value engineering
A26: Економія на будівельних витратах | B26: 0.04 | C26: стратегія: 3–5%; підтверджує QS
A27: Приріст прибутку | B27: ='Сценарій A'!$B$64*$B$26 -> 275820.6
A29: 4. Переговори про ціну землі
A30: Знижка на землю | B30: 140000 | C30: стратегія: £100–180k
A31: Приріст прибутку (з SDLT і фінансуванням землі) | B31: =$B$30*(1+Припущення!$B$41)*(1+Припущення!$B$35*(Припущення!$B$37+'Сценарій A'!$B$13)/12) -> 175112
A33: 5. Зниження витрат на продаж
A34: Зниження статті «маркетинг і агенти» | B34: 0.25 | C34: стратегія: £50–70k
A35: Приріст прибутку | B35: ='Сценарій A'!$B$48*$B$34 -> 57269.688
A37: 6. Траншеве залучення equity (довідково, НЕ в сумі)
A38: Equity разом | B38: 2560000 | C38: стратегія
A39: Priority return | B39: 0.12 | C39: стратегія
A40: Перший транш | B40: 800000 | C40: стратегія
A41: Строк, місяців | B41: 24
A42: Строк другого траншу, місяців | B42: 15
A43: Return при внесенні всього одразу | B43: =$B$38*$B$39*$B$41/12 -> 614400
A44: Return при траншах | B44: =$B$40*$B$39*$B$41/12+($B$38-$B$40)*$B$39*$B$42/12 -> 456000
A45: Економія | B45: =$B$43-$B$44 -> 158400 | C45: база моделі фінансується боргом 9%, а не equity 12% — тому не додаємо до суми
A47: Результат Improved Case
A48: Сума важелів 1–5 | B48: =$B$14+$B$23+$B$27+$B$31+$B$35 -> 642488
...

Sheet Припущення
A1: ZON Wivenhoe (Croquet Gardens) — припущення моделі
A2: Легенда: синій текст = вхідні дані (можна змінювати); чорний = формули; зелений = посилання на інший аркуш; жовта заливка = ключове припущення, яке треба замінити реальними даними перед показом інвесторам.
A4: Тип юніта | B4: GIA, м² | C4: Спальні | D4: Мешканців | E4: Поверхів | F4: NDSS мін., м² | G4: NDSS ок? | H4: Ціна продажу, £/м² | I4: Ціна юніта, £ | J4: Ділянка (сад+будинок), м² | K4: Джерело / примітка
A5: Lake House Compact 61 | B5: 61.5 | C5: 2 | D5: 3 | E5: 1 | F5: 61 | G5: =IF(B5>=F5,"Так","НІ") -> Так | H5: 4880 | I5: =B5*H5 -> 300120 | J5: 340 | K5: GIA з брифу. NDSS 2b3p 1 пов. = 61 м² (не проходить як 2b4p = 70). Ціна — припущення.
A6: Meadow 71 | B6: 71 | C6: 2 | D6: 4 | E6: 1 | F6: 70 | G6: =IF(B6>=F6,"Так","НІ") -> Так | H6: 4650 | I6: =B6*H6 -> 330150 | J6: 370 | K6: GIA з брифу. NDSS 2b4p 1 пов. = 70 м². Юніт для доступного житла S106. Ціна — припущення.
A7: Country 140 | B7: 140 | C7: 3 | D7: 6 | E7: 1 | F7: 95 | G7: =IF(B7>=F7,"Так","НІ") -> Так | H7: 4640 | I7: =B7*H7 -> 649600 | J7: 560 | K7: GIA з брифу. NDSS 3b6p 1 пов. = 95 м². Ціна — припущення.
A9: Ціни £/м² — ринкове припущення (~£430–455/фут²) для нових бунгало в CO7. Треба підтвердити звітом агента (Savills / Fenn Wright / Beresfords).
A11: Ділянка та планування
A12: Площа ділянки | B12: 14245 | C12: м² | D12: Від користувача: 3,52 акра
A13: Дороги, тротуари, паркування | B13: 0.18 | C13: % ділянки | D13: Припущення: петля Manual for Streets + гостьові місця
A14: SuDS-струмок, ставок, відкритий простір | B14: 0.1 | C14: % ділянки | D14: Припущення; уточнює інженер з дренажу
A15: BNG / ландшафтні буфери на ділянці | B15: 0.06 | C15: % ділянки | D15: Припущення; уточнює еколог (метрика DEFRA)
A16: Hub: забудова + тераса + паркування | B16: 900 | C16: м² | D16: Припущення: 175 м² пляма + тераса + ~10 місць
A18: Доступне житло (S106)
A19: Частка доступного житла | B19: 0.3 | C19: % юнітів | D19: Припущення за політикою Colchester; перевірити в угоді S106
A20: Ціна продажу RSL | B20: 0.6 | C20: % ринкової | D20: Припущення: мікс affordable rent + shared ownership
A22: Вартість будівництва
A23: Будівництво бунгало | B23: 2400 | C23: £/м² GIA | D23: Припущення, діапазон £2 100–2 800: високий клас, ASHP + PV + MVHR
A24: Будівництво ZON Hub | B24: 3000 | C24: £/м² GIA | D24: Припущення: змішане використання, комерційне обладнання
A25: Зовнішні роботи та мережі | B25: 0.15 | C25: % будівництва | D25: Припущення: дороги, SuDS, містки, мережі, підстанція
A26: Резерв на непередбачене | B26: 0.05 | C26: % буд.+зовн. | D26: Припущення
A27: Проєктування та консультанти | B27: 0.1 | C27: % буд.+зовн. | D27: Припущення
A28: Внески S106 / інфраструктура | B28: 15000 | C28: £/юніт | D28: Припущення; уточнити з угоди S106
A29: Essex Coast RAMS | B29: 160 | C29: £/юніт | D29: Приблизний тариф; перевірити поточну ставку
A30: BNG за межами ділянки (кредити) | B30: 50000 | C30: £ разом | D30: Припущення
A32: Продаж і фінансування
A33: Маркетинг і агенти | B33: 0.025 | C33: % GDV | D33: Припущення
A34: Юридичні витрати на продаж | B34: 1500 | C34: £/юніт | D34: Припущення
A35: Ставка девелоперського кредиту | B35: 0.09 | C35: % річних | D35: Припущення
A36: Середня вибірка кредиту | B36: 0.5 | C36: % витрат | D36: Стандартне спрощення S-кривої
A37: Програма: будівництво + продаж | B37: 24 | C37: місяців | D37: Припущення
A39: Земля і ціль
A40: Ціна землі | B40: 1500000 | C40: £ | D40: ЗАГЛУШКА — замінити фактичною ціною / ціною опціону
A41: SDLT + юридичні на землю | B41: 0.06 | C41: % ціни землі | D41: Припущення (ставки для нежитлової нерухомості)
A42: Цільова маржа девелопера | B42: 0.2 | C42: % GDV | D42: Типовий орієнтир кредиторів 17–20%
A44: ZON Hub (лише сценарій B)
A45: Hub GIA разом | B45: 350 | C45: м² | D45: Бриф: 175 + 175 м²
A46: Кав'ярня / коворкінг GIA | B46: 175 | C46: м² | D46: Бриф
A47: Оренда кав'ярні | B47: 150 | C47: £/м²/рік | D47: Припущення для невеликої локації
A48: Дохідність при оцінці кав'ярні | B48: 0.075 | C48: % | D48: Припущення (вторинна роздрібна торгівля)
...

Sheet Сценарій A
A1: Сценарій A — 25 бунгало в межах outline consent
A2: Шлях: Reserved Matters. Без Hub. Відповідає ліміту 25 юнітів (за словами користувача).
A4: Тип юніта | B4: К-сть | C4: GIA разом, м² | D4: Ціна юніта, £ | E4: GDV ринковий, £ | F4: Ділянки, м²
A5: =Припущення!$A$5 -> Lake House Compact 61 | B5: 9 | C5: =B5*Припущення!$B$5 -> 553.5 | D5: =Припущення!$I$5 -> 300120 | E5: =B5*D5 -> 2701080 | F5: =B5*Припущення!$J$5 -> 3060
A6: =Припущення!$A$6 -> Meadow 71 | B6: 9 | C6: =B6*Припущення!$B$6 -> 639 | D6: =Припущення!$I$6 -> 330150 | E6: =B6*D6 -> 2971350 | F6: =B6*Припущення!$J$6 -> 3330
A7: =Припущення!$A$7 -> Country 140 | B7: 7 | C7: =B7*Припущення!$B$7 -> 980 | D7: =Припущення!$I$7 -> 649600 | E7: =B7*D7 -> 4547200 | F7: =B7*Припущення!$J$7 -> 3920
A8: Разом бунгало | B8: =SUM(B5:B7) -> 25 | C8: =SUM(C5:C7) -> 2172.5 | E8: =SUM(E5:E7) -> 10219630 | F8: =SUM(F5:F7) -> 10310
A10: Параметри сценарію
A11: ZON Hub включено (1 = так, 0 = ні) | B11: 0
A12: Ймовірність отримати дозвіл | B12: 0.85 | C12: Експертна оцінка, не факт
A13: Додаткова затримка на планування | B13: 0 | C13: місяців; фінансування землі тим часом
A14: Витрати, якщо в дозволі відмовлять | B14: 100000 | C14: консультанти, звіти, апеляція
A15: Житлових юнітів разом | B15: =B8+$B$11*Припущення!$B$49 -> 25 | C15: бунгало + апартаменти Hub
A17: Баланс території
A18: Приватні ділянки | B18: =F8 -> 10310
A19: Дороги та паркування | B19: =Припущення!$B$12*Припущення!$B$13 -> 2564.1
A20: SuDS / відкритий простір | B20: =Припущення!$B$12*Припущення!$B$14 -> 1424.5
A21: BNG / буфери | B21: =Припущення!$B$12*Припущення!$B$15 -> 854.7
A22: ZON Hub | B22: =$B$11*Припущення!$B$16 -> 0
A23: Потрібно разом, м² | B23: =SUM($B$18:$B$22) -> 15153.3
A24: Доступно, м² | B24: =Припущення!$B$12 -> 14245
A25: Запас (+) / дефіцит (−), м² | B25: =$B$24-$B$23 -> -908.3
A26: Перевірка | B26: =IF($B$25>=0,"Вміщується","НЕ ВМІЩУЄТЬСЯ") -> НЕ ВМІЩУЄТЬСЯ
A27: Середня ділянка, м² | B27: =IF(B8>0,F8/B8,0) -> 412.4
A29: Виручка (GDV)
A30: Бунгало за ринковою ціною | B30: =E8 -> 10219630
A31: Юнітів доступного житла (вимога) | B31: =ROUNDUP($B$15*Припущення!$B$19,0) -> 8 | C31: округлення вгору від усіх житлових юнітів
A32: …з них покривається Meadow 71 | B32: =MIN($B$31,B6) -> 8
A33: Перевірка покриття | B33: =IF($B$32<$B$31,"Meadow замало — потрібні інші типи","OK") -> OK
A34: Знижка на доступне житло | B34: =-$B$31*D6*(1-Припущення!$B$20) -> -1056480 | C34: усі доступні юніти рахуються за ціною Meadow
A35: ZON Hub: кав'ярня (капіталізація) | B35: =$B$11*Припущення!$B$46*Припущення!$B$47/Припущення!$B$48 -> 0
A36: ZON Hub: апартаменти | B36: =$B$11*Припущення!$B$49*Припущення!$B$50 -> 0
A37: GDV разом | B37: =SUM($B$30,$B$34,$B$35,$B$36) -> 9163150
A39: Витрати (TDC)
A40: Будівництво бунгало | B40: =C8*Припущення!$B$23 -> 5214000
A41: Будівництво Hub | B41: =$B$11*Припущення!$B$45*Припущення!$B$24 -> 0
A42: Зовнішні роботи та мережі | B42: =($B$40+$B$41)*Припущення!$B$25 -> 782100
A43: Резерв | B43: =($B$40+$B$41+$B$42)*Припущення!$B$26 -> 299805
A44: Проєктування та консультанти | B44: =($B$40+$B$41+$B$42)*Припущення!$B$27 -> 599610
A45: S106 | B45: =$B$15*Припущення!$B$28 -> 375000
...

Sheet Сценарій B
A1: Сценарій B — бриф: 25 бунгало + ZON Hub (4 апартаменти + кав'ярня) = 29 житлових
A2: Шлях: бунгало в межах 25, але Hub додає 4 житла, клас E і короткострокову оренду — окрема / нова заявка. Ризик відмови.
A4: Тип юніта | B4: К-сть | C4: GIA разом, м² | D4: Ціна юніта, £ | E4: GDV ринковий, £ | F4: Ділянки, м²
A5: =Припущення!$A$5 -> Lake House Compact 61 | B5: 10 | C5: =B5*Припущення!$B$5 -> 615 | D5: =Припущення!$I$5 -> 300120 | E5: =B5*D5 -> 3001200 | F5: =B5*Припущення!$J$5 -> 3400
A6: =Припущення!$A$6 -> Meadow 71 | B6: 8 | C6: =B6*Припущення!$B$6 -> 568 | D6: =Припущення!$I$6 -> 330150 | E6: =B6*D6 -> 2641200 | F6: =B6*Припущення!$J$6 -> 2960
A7: =Припущення!$A$7 -> Country 140 | B7: 7 | C7: =B7*Припущення!$B$7 -> 980 | D7: =Припущення!$I$7 -> 649600 | E7: =B7*D7 -> 4547200 | F7: =B7*Припущення!$J$7 -> 3920
A8: Разом бунгало | B8: =SUM(B5:B7) -> 25 | C8: =SUM(C5:C7) -> 2163 | E8: =SUM(E5:E7) -> 10189600 | F8: =SUM(F5:F7) -> 10280
A10: Параметри сценарію
A11: ZON Hub включено (1 = так, 0 = ні) | B11: 1
A12: Ймовірність отримати дозвіл | B12: 0.45 | C12: Експертна оцінка, не факт
A13: Додаткова затримка на планування | B13: 12 | C13: місяців; фінансування землі тим часом
A14: Витрати, якщо в дозволі відмовлять | B14: 250000 | C14: консультанти, звіти, апеляція
A15: Житлових юнітів разом | B15: =B8+$B$11*Припущення!$B$49 -> 29 | C15: бунгало + апартаменти Hub
A17: Баланс території
A18: Приватні ділянки | B18: =F8 -> 10280
A19: Дороги та паркування | B19: =Припущення!$B$12*Припущення!$B$13 -> 2564.1
A20: SuDS / відкритий простір | B20: =Припущення!$B$12*Припущення!$B$14 -> 1424.5
A21: BNG / буфери | B21: =Припущення!$B$12*Припущення!$B$15 -> 854.7
A22: ZON Hub | B22: =$B$11*Припущення!$B$16 -> 900
A23: Потрібно разом, м² | B23: =SUM($B$18:$B$22) -> 16023.3
A24: Доступно, м² | B24: =Припущення!$B$12 -> 14245
A25: Запас (+) / дефіцит (−), м² | B25: =$B$24-$B$23 -> -1778.3
A26: Перевірка | B26: =IF($B$25>=0,"Вміщується","НЕ ВМІЩУЄТЬСЯ") -> НЕ ВМІЩУЄТЬСЯ
A27: Середня ділянка, м² | B27: =IF(B8>0,F8/B8,0) -> 411.2
A29: Виручка (GDV)
A30: Бунгало за ринковою ціною | B30: =E8 -> 10189600
A31: Юнітів доступного житла (вимога) | B31: =ROUNDUP($B$15*Припущення!$B$19,0) -> 9 | C31: округлення вгору від усіх житлових юнітів
A32: …з них покривається Meadow 71 | B32: =MIN($B$31,B6) -> 8
A33: Перевірка покриття | B33: =IF($B$32<$B$31,"Meadow замало — потрібні інші типи","OK") -> Meadow замало — потрібні інші типи
A34: Знижка на доступне житло | B34: =-$B$31*D6*(1-Припущення!$B$20) -> -1188540 | C34: усі доступні юніти рахуються за ціною Meadow
A35: ZON Hub: кав'ярня (капіталізація) | B35: =$B$11*Припущення!$B$46*Припущення!$B$47/Припущення!$B$48 -> 350000
A36: ZON Hub: апартаменти | B36: =$B$11*Припущення!$B$49*Припущення!$B$50 -> 880000
A37: GDV разом | B37: =SUM($B$30,$B$34,$B$35,$B$36) -> 10231060
A39: Витрати (TDC)
A40: Будівництво бунгало | B40: =C8*Припущення!$B$23 -> 5191200
A41: Будівництво Hub | B41: =$B$11*Припущення!$B$45*Припущення!$B$24 -> 1050000
A42: Зовнішні роботи та мережі | B42: =($B$40+$B$41)*Припущення!$B$25 -> 936180
A43: Резерв | B43: =($B$40+$B$41+$B$42)*Припущення!$B$26 -> 358869
A44: Проєктування та консультанти | B44: =($B$40+$B$41+$B$42)*Припущення!$B$27 -> 717738
A45: S106 | B45: =$B$15*Припущення!$B$28 -> 435000
...
